
2022-01-30 08:54:42,431:utility.py:utility:INFO:--------------------------------------------------------------------------------
sqlalchemy.exc.NoReferencedTableError: Foreign key associated with column 'customer_account.account_id' could not find table 'bankaccount' with which to generate a foreign key to target column 'id'
2022-01-30 21:17:17,494:utility.py:utility:INFO:Customer-account connection: (101, 104) failed.
2022-01-30 21:18:10,891:utility.py:utility:INFO:hello
2022-01-30 21:18:11,061:utility.py:utility:INFO:Foreign key associated with column 'customer_account.account_id' could not find table 'bankaccount' with which to generate a foreign key to target column 'id'
2022-01-30 21:18:11,082:utility.py:utility:INFO:Customer-account connection: (101, 104) failed.
2022-01-30 21:31:57,018:utility.py:utility:INFO:hello
2022-01-30 21:31:57,380:utility.py:utility:INFO:Foreign key associated with column 'customer_account.account_id' could not find table 'bankaccount' with which to generate a foreign key to target column 'id'
2022-01-30 21:31:57,412:utility.py:utility:INFO:Customer-account connection: (101, 104) failed.
2022-01-30 21:33:34,806:utility.py:utility:INFO:hello
2022-01-30 21:33:34,982:utility.py:utility:INFO:Foreign key associated with column 'customer_account.customer_id' could not find table 'customer' with which to generate a foreign key to target column 'id'
2022-01-30 21:33:34,990:utility.py:utility:INFO:Customer-account connection: (101, 104) failed.
2022-01-30 21:34:28,777:utility.py:utility:INFO:hello
2022-01-30 21:34:29,005:utility.py:utility:INFO:Customer-account connection: (101, 104) failed.
2022-01-30 21:35:05,674:utility.py:utility:INFO:hello
2022-01-30 21:35:05,817:utility.py:utility:INFO:Customer-account connection: (101, 104) failed.
2022-01-30 21:36:13,947:utility.py:utility:INFO:hello
2022-01-30 21:36:14,117:utility.py:utility:INFO:Customer-account connection: (101, 104) failed.
2022-01-30 21:36:53,210:utility.py:utility:INFO:hello
2022-01-30 21:36:53,408:utility.py:utility:INFO:Customer-account connection: (101, 104) created.
2022-01-30 21:44:16,499:utility.py:utility:INFO:hello
2022-01-30 21:44:16,831:utility.py:utility:INFO:Customer-account connection: (101, 104) created.
2022-01-30 21:53:23,657:utility.py:utility:INFO:hello
2022-01-30 21:53:25,090:utility.py:utility:INFO:(pymysql.err.ProgrammingError) (1146, "Table 'bank.ass_customer_account' doesn't exist")
[SQL: INSERT INTO ass_customer_account (customer_id, account_id, cr_datetime) VALUES (%(customer_id)s, %(account_id)s, %(cr_datetime)s)]
[parameters: {'customer_id': 100, 'account_id': 175, 'cr_datetime': datetime.datetime(2022, 1, 30, 21, 53, 25, 76602)}]
(Background on this error at: https://sqlalche.me/e/14/f405)
2022-01-30 21:53:25,140:utility.py:utility:INFO:Account creation failed -- customer-account assignment failed
2022-01-30 21:53:25,142:utility.py:utility:INFO:account creationng fails -- customer_id 100not found.
2022-01-30 21:55:31,349:utility.py:utility:INFO:hello
2022-01-30 21:55:31,504:utility.py:utility:INFO:(pymysql.err.ProgrammingError) (1146, "Table 'bank.ass_customer_account' doesn't exist")
[SQL: INSERT INTO ass_customer_account (customer_id, account_id, cr_datetime) VALUES (%(customer_id)s, %(account_id)s, %(cr_datetime)s)]
[parameters: {'customer_id': 101, 'account_id': 104, 'cr_datetime': datetime.datetime(2022, 1, 30, 21, 55, 31, 497937)}]
(Background on this error at: https://sqlalche.me/e/14/f405)
2022-01-30 21:55:31,525:utility.py:utility:INFO:Customer-account connection: (101, 104) failed.
2022-01-30 21:58:37,489:utility.py:utility:INFO:hello
2022-01-30 21:58:37,704:utility.py:utility:INFO:Customer-account connection: (101, 104) created.
2022-01-30 21:58:57,749:utility.py:utility:INFO:hello
2022-01-30 21:58:57,926:utility.py:utility:INFO:Customer-account connection: (101, 104) created.
2022-01-30 21:59:31,914:utility.py:utility:INFO:hello
2022-01-30 21:59:32,530:utility.py:utility:INFO:Account successfully created and assgined to customer.
2022-01-30 21:59:32,609:utility.py:utility:INFO:Account successfully created and assgined to customer.
2022-01-30 22:00:11,637:utility.py:utility:INFO:hello
2022-01-30 22:00:12,450:utility.py:utility:INFO:Account successfully created and assgined to customer.
2022-01-30 22:00:12,507:utility.py:utility:INFO:Account successfully created and assgined to customer.
2022-01-30 22:04:41,477:utility.py:utility:INFO:hello
2022-01-30 22:04:42,591:utility.py:utility:INFO:Account (id =180) successfully created and assgined to customer (id=100).
2022-01-30 22:05:48,220:utility.py:utility:INFO:hello
2022-01-30 22:05:49,250:utility.py:utility:INFO:Account (id =181) successfully created and assgined to customer (id=100).
2022-01-30 22:06:20,555:utility.py:utility:INFO:hello
2022-01-30 22:06:21,222:utility.py:utility:INFO:Account (id =182) successfully created and assgined to customer (id=100).
2022-01-30 22:07:04,519:utility.py:utility:INFO:hello
2022-01-30 22:07:05,526:utility.py:utility:INFO:Account (id =183) successfully created and assgined to customer (id=100).
2022-01-30 22:08:49,904:utility.py:utility:INFO:hello
2022-01-30 22:08:51,097:utility.py:utility:INFO:Account (id =184) successfully created and assgined to customer (id=100).
2022-01-30 22:08:51,098:utility.py:utility:INFO:Account: BankAccount(184, 20184, 'checking', 400.0)
2022-01-30 22:09:13,233:utility.py:utility:INFO:hello
2022-01-30 22:09:13,899:utility.py:utility:INFO:Account (id =185) successfully created and assgined to customer (id=100).
2022-01-30 22:09:13,900:utility.py:utility:INFO:Account: BankAccount(185, 20185, 'checking', 400.0)
2022-01-30 22:09:13,900:utility.py:utility:INFO:Customer: Customer(100, 'mary', 'kirkland')
2022-01-30 22:09:47,852:utility.py:utility:INFO:hello
2022-01-30 22:09:48,574:utility.py:utility:INFO:Account (id =186) successfully created and assgined to customer (id=100).
2022-01-30 22:09:48,575:utility.py:utility:INFO:	 BankAccount(186, 20186, 'checking', 400.0)
2022-01-30 22:09:48,575:utility.py:utility:INFO:	 Customer(100, 'mary', 'kirkland')
2022-01-31 08:48:12,829:utility.py:utility:INFO:hello
2022-01-31 08:48:13,299:utility.py:utility:INFO:Account (id =189) successfully created and assgined to customer (id=100).
2022-01-31 08:48:13,299:utility.py:utility:INFO:	 BankAccount(189, 20189, 'checking', 400.0)
2022-01-31 08:48:13,302:utility.py:utility:INFO:	 Customer(100, 'mary', 'kirkland')
2022-01-31 08:48:35,454:utility.py:utility:INFO:hello
2022-01-31 08:48:35,918:utility.py:utility:INFO:Account (id =190) successfully created and assgined to customer (id=100).
2022-01-31 08:48:35,918:utility.py:utility:INFO:	 BankAccount(190, 20190, 'checking', 400.0)
2022-01-31 08:48:35,918:utility.py:utility:INFO:	 Customer(100, 'mary', 'kirkland')
2022-01-31 08:48:55,755:utility.py:utility:INFO:hello
2022-01-31 08:48:56,213:utility.py:utility:INFO:Account (id =191) successfully created and assgined to customer (id=100).
2022-01-31 08:48:56,214:utility.py:utility:INFO:	 BankAccount(191, 20191, 'checking', 400.0)
2022-01-31 08:48:56,214:utility.py:utility:INFO:	 Customer(100, 'mary', 'kirkland')
2022-01-31 08:49:05,222:utility.py:utility:INFO:hello
2022-01-31 08:49:05,334:utility.py:utility:INFO:found the account
2022-01-31 08:49:05,354:utility.py:utility:INFO:Withdraw transaction succeeded
2022-01-31 08:49:05,356:utility.py:utility:INFO:Transaction id: 20172; amount withdrawn: 10 account balance: 320.0 
2022-01-31 08:49:05,356:utility.py:utility:INFO:Withdraw transaction succeeded
2022-01-31 08:51:40,278:utility.py:utility:INFO:hello
2022-01-31 10:35:29,280:utility.py:utility:INFO:hello
2022-01-31 10:36:39,261:utility.py:utility:INFO:hello
2022-01-31 10:36:58,997:utility.py:utility:INFO:hello
2022-01-31 10:38:20,167:utility.py:utility:INFO:hello
2022-01-31 10:45:18,964:utility.py:utility:INFO:hello
2022-01-31 10:45:54,372:utility.py:utility:INFO:hello
2022-01-31 10:47:39,722:utility.py:utility:INFO:hello
2022-01-31 10:47:50,758:utility.py:utility:INFO:hello
2022-01-31 10:50:37,416:utility.py:utility:INFO:hello
2022-01-31 10:51:27,313:utility.py:utility:INFO:hello
2022-01-31 12:14:55,115:utility.py:utility:INFO:hello
2022-01-31 12:14:55,491:acctransaction.py:utility:INFO:Deposit transaction succeeded
2022-01-31 12:14:55,495:acctransaction.py:utility:INFO:Transaction id: 42; amount deposited: 25.0; account balance: 545.0 
2022-02-01 16:23:09,309:utility.py:utility:INFO:hello
2022-02-01 16:23:28,349:utility.py:utility:INFO:hello
2022-02-01 16:24:13,673:utility.py:utility:INFO:hello
2022-02-01 16:24:14,388:utility.py:utility:INFO:(pymysql.err.DataError) (1366, "Incorrect integer value: 'c' for column 'balance' at row 1")
[SQL: INSERT INTO bankaccount (account_no, account_type, balance, intrst_rate, cr_date) VALUES (%(account_no)s, %(account_type)s, %(balance)s, %(intrst_rate)s, %(cr_date)s)]
[parameters: {'account_no': None, 'account_type': 'savings', 'balance': 'c', 'intrst_rate': 400, 'cr_date': datetime.datetime(2022, 2, 1, 16, 24, 14, 112039)}]
(Background on this error at: https://sqlalche.me/e/14/9h9h)
2022-02-01 16:24:14,472:utility.py:utility:INFO:Account creation fails -- save to db failed
2022-02-01 16:25:41,807:utility.py:utility:INFO:hello
2022-02-01 16:34:02,590:utility.py:utility:INFO:hello
2022-02-01 16:36:12,971:utility.py:utility:INFO:hello
2022-02-01 16:36:13,489:utility.py:utility:INFO:Account (id ={}) successfully created.
2022-02-01 16:36:13,492:utility.py:utility:INFO:	 BankAccount(194, 20194, 'checking', 400.0)
2022-02-01 16:36:52,260:utility.py:utility:INFO:hello
2022-02-01 16:36:52,742:utility.py:utility:INFO:Account (id =195) successfully created.
2022-02-01 16:36:52,743:utility.py:utility:INFO:	 BankAccount(195, 20195, 'checking', 400.0)
2022-02-01 16:40:21,839:utility.py:utility:INFO:hello
2022-02-01 16:40:22,528:utility.py:utility:INFO:Account (id =196) successfully created.
2022-02-01 16:40:22,528:utility.py:utility:INFO:	 BankAccount(196, 20196, 'checking', 400.0)
2022-02-01 16:41:28,874:utility.py:utility:INFO:hello
2022-02-01 16:41:29,204:utility.py:utility:INFO:account creationng fails -- customer_id 100not found.
2022-02-01 16:43:39,059:utility.py:utility:INFO:hello
2022-02-01 16:43:39,643:utility.py:utility:INFO:account creationng fails -- customer_id 101 not found.
2022-02-01 16:44:30,433:utility.py:utility:INFO:hello
2022-02-01 16:46:00,200:utility.py:utility:INFO:hello
2022-02-01 16:46:00,535:utility.py:utility:INFO:'NoneType' object has no attribute 'query'
2022-02-01 16:47:32,780:utility.py:utility:INFO:hello
2022-02-01 16:48:34,852:utility.py:utility:INFO:hello
2022-02-01 16:50:20,792:utility.py:utility:INFO:hello
2022-02-01 16:50:21,546:utility.py:utility:INFO:Account (id =197) successfully created.
2022-02-01 16:50:21,547:utility.py:utility:INFO:	 BankAccount(197, 20197, 'checking', 0.0)
2022-02-01 16:50:21,570:utility.py:utility:INFO:Account (id =197) successfully created and assgined to customer (id=101).
2022-02-01 16:50:21,572:utility.py:utility:INFO:	 BankAccount(197, 20197, 'checking', 0.0)
2022-02-01 16:50:21,572:utility.py:utility:INFO:	 Customer(101, 'tom', '4B Blue Ridge Blvd, Brighton, MI')
2022-02-01 21:06:11,020:utility.py:utility:INFO:hello
2022-02-01 21:08:19,753:utility.py:utility:INFO:hello
2022-02-01 21:08:34,126:utility.py:utility:INFO:hello
2022-02-01 21:10:21,795:utility.py:utility:INFO:hello
2022-02-01 21:10:22,405:utility.py:utility:INFO:'Query' object has no attribute 'filteryBy'
2022-02-01 21:10:46,144:utility.py:utility:INFO:hello
2022-02-01 21:10:46,562:utility.py:utility:INFO:'Query' object has no attribute 'filteryBy'
2022-02-01 21:19:08,020:utility.py:utility:INFO:hello
2022-02-01 21:19:08,420:utility.py:utility:INFO:'Query' object has no attribute 'filteryBy'
2022-02-01 21:19:30,205:utility.py:utility:INFO:hello
2022-02-01 21:22:05,584:utility.py:utility:INFO:hello
2022-02-01 21:22:06,004:utility.py:utility:INFO:'>' not supported between instances of 'DeclarativeMeta' and 'int'
2022-02-01 21:22:15,296:utility.py:utility:INFO:hello
2022-02-01 21:22:23,083:utility.py:utility:INFO:hello
2022-02-01 21:22:46,188:utility.py:utility:INFO:hello
2022-02-02 06:47:27,996:utility.py:utility:INFO:hello
2022-02-02 06:50:31,716:utility.py:utility:INFO:hello
2022-02-02 06:50:45,294:utility.py:utility:INFO:hello
2022-02-02 06:50:45,388:utility.py:utility:INFO:(pymysql.err.IntegrityError) (1062, "Duplicate entry '1' for key 'sequence.PRIMARY'")
[SQL: INSERT INTO sequence (id) VALUES (%(id)s)]
[parameters: {'id': 1}]
(Background on this error at: https://sqlalche.me/e/14/gkpj)
2022-02-02 06:55:39,547:utility.py:utility:INFO:hello
2022-02-02 06:55:39,656:utility.py:utility:INFO:(pymysql.err.IntegrityError) (1062, "Duplicate entry '1' for key 'sequence.PRIMARY'")
[SQL: INSERT INTO sequence (id) VALUES (%(id)s)]
[parameters: {'id': 1}]
(Background on this error at: https://sqlalche.me/e/14/gkpj)
2022-02-02 06:57:53,579:utility.py:utility:INFO:(pymysql.err.IntegrityError) (1062, "Duplicate entry '1' for key 'sequence.PRIMARY'")
[SQL: INSERT INTO sequence (id) VALUES (%(id)s)]
[parameters: {'id': 1}]
(Background on this error at: https://sqlalche.me/e/14/gkpj)
2022-02-02 06:57:53,595:utility.py:utility:INFO:(pymysql.err.IntegrityError) (1062, "Duplicate entry '1' for key 'sequence.PRIMARY'")
[SQL: INSERT INTO sequence (id) VALUES (%(id)s)]
[parameters: {'id': 1}]
(Background on this error at: https://sqlalche.me/e/14/gkpj)
2022-02-02 07:06:11,082:utility.py:utility:INFO:'int' object has no attribute 'id'
2022-02-02 07:06:30,877:utility.py:utility:INFO:'int' object has no attribute 'id'
2022-02-02 07:07:05,651:utility.py:utility:INFO:name 'rec' is not defined
2022-02-02 07:17:40,449:utility.py:utility:INFO:Multiple rows were found when exactly one was required
2022-02-02 07:17:40,464:utility.py:utility:INFO:Multiple rows were found when exactly one was required
2022-02-02 07:18:50,446:utility.py:utility:INFO:No row was found when one was required
2022-02-02 07:18:50,446:utility.py:utility:INFO:No row was found when one was required
2022-02-02 07:18:50,462:utility.py:utility:INFO:Multiple rows were found when exactly one was required
2022-02-02 07:18:50,478:utility.py:utility:INFO:Multiple rows were found when exactly one was required
2022-02-02 07:19:04,581:utility.py:utility:INFO:No row was found when one was required
2022-02-02 07:19:04,597:utility.py:utility:INFO:No row was found when one was required
2022-02-02 07:19:04,613:utility.py:utility:INFO:Multiple rows were found when exactly one was required
2022-02-02 07:19:04,613:utility.py:utility:INFO:Multiple rows were found when exactly one was required
2022-02-02 07:20:44,937:utility.py:utility:INFO:No row was found when one was required
2022-02-02 07:20:44,953:utility.py:utility:INFO:No row was found when one was required
2022-02-02 07:20:44,968:utility.py:utility:INFO:Multiple rows were found when exactly one was required
2022-02-02 07:20:44,984:utility.py:utility:INFO:Multiple rows were found when exactly one was required
2022-02-02 07:32:18,955:utility.py:utility:INFO:No row was found when one was required
2022-02-02 07:32:18,955:utility.py:utility:INFO:No row was found when one was required
2022-02-02 07:32:18,970:utility.py:utility:INFO:Multiple rows were found when exactly one was required
2022-02-02 07:32:18,970:utility.py:utility:INFO:Multiple rows were found when exactly one was required
2022-02-02 07:33:07,771:utility.py:utility:INFO:No row was found when one was required
2022-02-02 07:33:07,787:utility.py:utility:INFO:No row was found when one was required
2022-02-02 07:33:07,803:utility.py:utility:INFO:Multiple rows were found when exactly one was required
2022-02-02 07:33:07,803:utility.py:utility:INFO:Multiple rows were found when exactly one was required
2022-02-02 07:34:03,533:utility.py:utility:INFO:No row was found when one was required
2022-02-02 07:34:03,549:utility.py:utility:INFO:No row was found when one was required
2022-02-02 07:34:03,549:utility.py:utility:INFO:Multiple rows were found when exactly one was required
2022-02-02 07:34:03,564:utility.py:utility:INFO:Multiple rows were found when exactly one was required
2022-02-02 07:35:48,687:utility.py:utility:INFO:No row was found when one was required
2022-02-02 07:35:48,687:utility.py:utility:INFO:No row was found when one was required
2022-02-02 07:35:48,703:utility.py:utility:INFO:Multiple rows were found when exactly one was required
2022-02-02 07:35:48,703:utility.py:utility:INFO:Multiple rows were found when exactly one was required
2022-02-02 10:01:12,626:utility.py:utility:INFO:No row was found when one was required
2022-02-02 10:02:17,966:utility.py:utility:INFO:No row was found when one was required
2022-02-02 11:37:51,771:utility.py:utility:INFO:Account (id =204) successfully created and assgined to customer (id=101).
2022-02-02 11:37:51,771:utility.py:utility:INFO:	 BankAccount(204, 30514, 'savings', 200.0)
2022-02-02 11:37:51,771:utility.py:utility:INFO:	 Customer(101, 'tom', '4B Blue Ridge Blvd, Brighton, MI')
2022-02-02 11:38:54,749:utility.py:utility:INFO:Account (id =205) successfully created and assgined to customer (id=101).
2022-02-02 11:38:54,749:utility.py:utility:INFO:	 BankAccount(205, 30515, 'savings', 900.0)
2022-02-02 11:38:54,749:utility.py:utility:INFO:	 Customer(101, 'tom', '4B Blue Ridge Blvd, Brighton, MI')
2022-02-02 11:39:50,513:utility.py:utility:INFO:Account (id =206) successfully created and assgined to customer (id=101).
2022-02-02 11:39:50,513:utility.py:utility:INFO:	 BankAccount(206, 20516, 'checking', 900.0)
2022-02-02 11:39:50,513:utility.py:utility:INFO:	 Customer(101, 'tom', '4B Blue Ridge Blvd, Brighton, MI')
2022-02-02 11:40:28,699:utility.py:utility:INFO:Account (id =207) successfully created and assgined to customer (id=101).
2022-02-02 11:40:28,699:utility.py:utility:INFO:	 BankAccount(207, 30517, 'savings', 900.0)
2022-02-02 11:40:28,699:utility.py:utility:INFO:	 Customer(101, 'tom', '4B Blue Ridge Blvd, Brighton, MI')
2022-02-02 12:07:15,673:utility.py:utility:INFO:Account (id =208) successfully created and assgined to customer (id=101).
2022-02-02 12:07:15,673:utility.py:utility:INFO:	 BankAccount(id=208, account_no=30522, account_type='savings', balance=900.0)
2022-02-02 12:07:15,673:utility.py:utility:INFO:	 Customer(101, 'tom', '4B Blue Ridge Blvd, Brighton, MI')
2022-02-02 12:12:02,174:utility.py:utility:INFO:Account (id =209) successfully created and assgined to customer (id=101).
2022-02-02 12:12:02,174:utility.py:utility:INFO:	 BankAccount(id=209, account_no=30523, account_type='savings', balance=200.0)
2022-02-02 12:12:02,174:utility.py:utility:INFO:	 Customer(101, 'tom', '4B Blue Ridge Blvd, Brighton, MI')
2022-02-02 12:17:19,488:utility.py:utility:INFO:Account (id =210) successfully created and assgined to customer (id=101).
2022-02-02 12:17:19,503:utility.py:utility:INFO:	 BankAccount(id=210, account_no=30524, account_type='savings', balance=200.0)
2022-02-02 12:17:19,503:utility.py:utility:INFO:	 Customer(101, 'tom', '4B Blue Ridge Blvd, Brighton, MI')
2022-02-02 12:23:54,486:utility.py:utility:INFO:Account (id =211) successfully created and assgined to customer (id=101).
2022-02-02 12:23:54,486:utility.py:utility:INFO:	 BankAccount(id=211, account_no=30525, account_type='savings', balance=200.0)
2022-02-02 12:23:54,486:utility.py:utility:INFO:	 Customer(101, 'tom', '4B Blue Ridge Blvd, Brighton, MI')
2022-02-02 12:24:51,986:utility.py:utility:INFO:Account (id =212) successfully created and assgined to customer (id=101).
2022-02-02 12:24:51,986:utility.py:utility:INFO:	 BankAccount(id=212, account_no=30526, account_type='savings', balance=300.0)
2022-02-02 12:24:51,986:utility.py:utility:INFO:	 Customer(101, 'tom', '4B Blue Ridge Blvd, Brighton, MI')
2022-02-02 12:25:30,433:utility.py:utility:INFO:Account (id =213) successfully created and assgined to customer (id=101).
2022-02-02 12:25:30,433:utility.py:utility:INFO:	 BankAccount(id=213, account_no=30527, account_type='savings', balance=300.0)
2022-02-02 12:25:30,433:utility.py:utility:INFO:	 Customer(101, 'tom', '4B Blue Ridge Blvd, Brighton, MI')
2022-02-02 14:39:20,027:utility.py:utility:INFO:(pymysql.err.OperationalError) (1054, "Unknown column 'level' in 'field list'")
[SQL: INSERT INTO employee (name, level, project) VALUES (%(name)s, %(level)s, %(project)s)]
[parameters: {'name': 'tom', 'level': None, 'project': None}]
(Background on this error at: https://sqlalche.me/e/14/e3q8)
2022-02-02 14:39:20,042:utility.py:utility:INFO:(pymysql.err.OperationalError) (1054, "Unknown column 'level' in 'field list'")
[SQL: INSERT INTO employee (name, level, project) VALUES (%(name)s, %(level)s, %(project)s)]
[parameters: {'name': 'tom', 'level': None, 'project': None}]
(Background on this error at: https://sqlalche.me/e/14/e3q8)
2022-02-02 14:39:40,962:utility.py:utility:INFO:(pymysql.err.OperationalError) (1054, "Unknown column 'level' in 'field list'")
[SQL: INSERT INTO employee (name, level, project) VALUES (%(name)s, %(level)s, %(project)s)]
[parameters: {'name': 'tom', 'level': None, 'project': None}]
(Background on this error at: https://sqlalche.me/e/14/e3q8)
2022-02-02 14:39:40,978:utility.py:utility:INFO:(pymysql.err.OperationalError) (1054, "Unknown column 'level' in 'field list'")
[SQL: INSERT INTO employee (name, level, project) VALUES (%(name)s, %(level)s, %(project)s)]
[parameters: {'name': 'tom', 'level': None, 'project': None}]
(Background on this error at: https://sqlalche.me/e/14/e3q8)
2022-02-02 14:39:40,978:utility.py:utility:INFO:The employee creation faild.
2022-02-02 14:42:20,162:utility.py:utility:INFO:The employee has been created.
2022-02-02 14:42:20,162:utility.py:utility:INFO:Employee(1, 'tom', '5a3a0a0')
2022-02-02 14:44:01,759:utility.py:utility:INFO:The employee has been created.
2022-02-02 14:44:31,446:utility.py:utility:INFO:The employee has been created.
2022-02-02 14:44:54,134:utility.py:utility:INFO:The employee has been created.
2022-02-02 14:50:21,175:utility.py:utility:INFO:tmpseq=
2022-02-02 14:55:43,341:utility.py:utility:INFO:Multiple rows were found when exactly one was required
2022-02-02 14:55:43,357:utility.py:utility:INFO:Multiple rows were found when exactly one was required
2022-02-02 14:56:51,762:utility.py:utility:INFO:tmpseq=
2022-02-02 15:30:05,281:utility.py:utility:INFO:The employee has been created.
2022-02-02 15:30:05,281:utility.py:utility:INFO:Employee(5,tom,a0554)
2022-02-02 15:34:59,737:utility.py:utility:INFO:The employee has been created.
2022-02-02 15:34:59,737:utility.py:utility:INFO:Employee(6,marry,a0555)
2022-02-02 15:36:07,806:utility.py:utility:INFO:The employee has been created.
2022-02-02 15:36:07,806:utility.py:utility:INFO:Employee(id=7,name=tom,login=a0556)
2022-02-02 15:37:39,427:utility.py:utility:INFO:The employee has been created.
2022-02-02 15:37:39,427:utility.py:utility:INFO:Employee(id=8,name='marry',login='a0557')
2022-02-02 15:38:43,319:utility.py:utility:INFO:The employee has been created.
2022-02-02 15:38:43,319:utility.py:utility:INFO:Employee(id=9,name='marry',login='a0558, password='558')
2022-02-02 18:10:14,476:utility.py:utility:INFO:The employee has been created.
2022-02-02 18:10:14,482:utility.py:utility:INFO:Employee(id=10,name='tom',login='a0559', password='559')
2022-02-02 18:24:08,624:utility.py:utility:INFO:(pymysql.err.OperationalError) (1364, "Field 'ticket_id' doesn't have a default value")
[SQL: INSERT INTO ticket_sale (trans_date, event_id, event_name, event_date, event_type, event_city, customer_id, price, num_tickets) VALUES (%(trans_date)s, %(event_id)s, %(event_name)s, %(event_date)s, %(event_type)s, %(event_city)s, %(customer_id)s, %(price)s, %(num_tickets)s)]
[parameters: {'trans_date': None, 'event_id': None, 'event_name': None, 'event_date': None, 'event_type': None, 'event_city': None, 'customer_id': None, 'price': None, 'num_tickets': None}]
(Background on this error at: https://sqlalche.me/e/14/e3q8)
2022-02-02 18:24:08,654:utility.py:utility:INFO:(pymysql.err.OperationalError) (1364, "Field 'ticket_id' doesn't have a default value")
[SQL: INSERT INTO ticket_sale (trans_date, event_id, event_name, event_date, event_type, event_city, customer_id, price, num_tickets) VALUES (%(trans_date)s, %(event_id)s, %(event_name)s, %(event_date)s, %(event_type)s, %(event_city)s, %(customer_id)s, %(price)s, %(num_tickets)s)]
[parameters: {'trans_date': None, 'event_id': None, 'event_name': None, 'event_date': None, 'event_type': None, 'event_city': None, 'customer_id': None, 'price': None, 'num_tickets': None}]
(Background on this error at: https://sqlalche.me/e/14/e3q8)
2022-02-02 18:26:38,595:utility.py:utility:INFO:(pymysql.err.OperationalError) (1364, "Field 'ticket_id' doesn't have a default value")
[SQL: INSERT INTO ticket_sale (trans_date, event_id, event_name, event_date, event_type, event_city, customer_id, price, num_tickets) VALUES (%(trans_date)s, %(event_id)s, %(event_name)s, %(event_date)s, %(event_type)s, %(event_city)s, %(customer_id)s, %(price)s, %(num_tickets)s)]
[parameters: {'trans_date': None, 'event_id': None, 'event_name': None, 'event_date': None, 'event_type': None, 'event_city': None, 'customer_id': None, 'price': None, 'num_tickets': None}]
(Background on this error at: https://sqlalche.me/e/14/e3q8)
2022-02-02 18:26:38,616:utility.py:utility:INFO:(pymysql.err.OperationalError) (1364, "Field 'ticket_id' doesn't have a default value")
[SQL: INSERT INTO ticket_sale (trans_date, event_id, event_name, event_date, event_type, event_city, customer_id, price, num_tickets) VALUES (%(trans_date)s, %(event_id)s, %(event_name)s, %(event_date)s, %(event_type)s, %(event_city)s, %(customer_id)s, %(price)s, %(num_tickets)s)]
[parameters: {'trans_date': None, 'event_id': None, 'event_name': None, 'event_date': None, 'event_type': None, 'event_city': None, 'customer_id': None, 'price': None, 'num_tickets': None}]
(Background on this error at: https://sqlalche.me/e/14/e3q8)
2022-02-03 06:21:19,296:utility.py:utility:INFO:(pymysql.err.IntegrityError) (1062, "Duplicate entry '3' for key 'ticket_sale.PRIMARY'")
[SQL: INSERT INTO ticket_sale (ticket_id, trans_date, event_id, event_name, event_date, event_type, event_city, customer_id, price, num_tickets) VALUES (%(ticket_id)s, %(trans_date)s, %(event_id)s, %(event_name)s, %(event_date)s, %(event_type)s, %(event_city)s, %(customer_id)s, %(price)s, %(num_tickets)s)]
[parameters: {'ticket_id': 3, 'trans_date': None, 'event_id': 39, 'event_name': None, 'event_date': None, 'event_type': None, 'event_city': None, 'customer_id': None, 'price': 300, 'num_tickets': None}]
(Background on this error at: https://sqlalche.me/e/14/gkpj)
2022-02-03 06:21:19,322:utility.py:utility:INFO:(pymysql.err.IntegrityError) (1062, "Duplicate entry '3' for key 'ticket_sale.PRIMARY'")
[SQL: INSERT INTO ticket_sale (ticket_id, trans_date, event_id, event_name, event_date, event_type, event_city, customer_id, price, num_tickets) VALUES (%(ticket_id)s, %(trans_date)s, %(event_id)s, %(event_name)s, %(event_date)s, %(event_type)s, %(event_city)s, %(customer_id)s, %(price)s, %(num_tickets)s)]
[parameters: {'ticket_id': 3, 'trans_date': None, 'event_id': 39, 'event_name': None, 'event_date': None, 'event_type': None, 'event_city': None, 'customer_id': None, 'price': 300, 'num_tickets': None}]
(Background on this error at: https://sqlalche.me/e/14/gkpj)
